<?xml version="1.0"?>
<robot name="mbot" xmlns:xacro="http://www.ros.org/wiki/xacro">

  <!-- Gazebo: Color & Sensor -->
  <xacro:include filename="$(find model)/urdf/mbotModel.gazebo" />
  
  <!-- COLOR -->
  <material name="black">
    <color rgba="0 0 0 1"/>
  </material>
  
  <material name="gray">
    <color rgba="0.609 0.633 0.634 1.0"/>
  </material>

  <material name="white">
    <color rgba="1.0 1.0 1.0 1.0"/>
  </material>

  <!-- links -->
  <!-- <link name="dummy"></link> -->
  <link name="base_link">
  </link>

  <link name="body_link">
    <visual>
      <geometry>
        <mesh filename="package://model/meshes/dashgoD1_body.stl"/>
      </geometry>
      <origin rpy="0 3.1415 1.57075" xyz="0.203 0.203 0.196 "/>
      <material name="black"/>
    </visual>
    <collision>
      <geometry>
        <mesh filename="package://model/meshes/dashgoD1_body.stl"/>
      </geometry>
      <origin rpy="0 3.1415 1.57075" xyz="0.203 0.203 0.196 "/>
    </collision>
    <inertial>
      <mass value="10.0"/>
      <inertia ixx="1.0" ixy="0.0" ixz="0.0" iyy="1.0" iyz="0.0" izz="1.0"/>
    </inertial>
  </link>
  
  <link name="left_leg">
    <visual>
      <geometry>
        <cylinder length="0.035" radius="0.0625"/>
      </geometry>
      <origin rpy="0 1.57075 0" xyz="0.17535 0 0"/>
      <material name="gray"/>
    </visual>
    <collision>
      <geometry>
        <cylinder length="0.035" radius="0.0625"/>
      </geometry>
      <origin rpy="0 1.57075 0" xyz="0.17535 0 0"/>
    </collision>
    <inertial>
      <mass value="10.0"/>
      <inertia ixx="1.0" ixy="0.0" ixz="0.0" iyy="1.0" iyz="0.0" izz="1.0"/>
    </inertial>
  </link>
  
  <link name="right_leg">
    <visual>
      <geometry>
        <cylinder length="0.035" radius="0.0625"/>
      </geometry>
      <origin rpy="0 1.57075 0" xyz="-0.17535 0 0"/>
      <material name="gray"/>
    </visual>
    <collision>
      <geometry>
        <cylinder length="0.035" radius="0.0625"/>
      </geometry>
      <origin rpy="0 1.57075 0" xyz="-0.17535 0 0"/>
    </collision>
    <inertial>
      <mass value="10.0"/>
      <inertia ixx="1.0" ixy="0.0" ixz="0.0" iyy="1.0" iyz="0.0" izz="1.0"/>
    </inertial>
  </link>
  
  <link name="front_support_of_steering_wheel_frame">
    <visual>
      <geometry>
        <cylinder radius="0.0025" length="0.0025"/>
      </geometry>
      <origin rpy="0 0 0" xyz="0 0 0"/>
      <material name="white"/>
    </visual>
    <collision>
      <geometry>
        <cylinder radius="0.0025" length="0.0025"/>
      </geometry>
      <origin rpy="0 0 0" xyz="0 0 0"/>
    </collision>
    <inertial>
      <mass value="10.0"/>
      <inertia ixx="1.0" ixy="0.0" ixz="0.0" iyy="1.0" iyz="0.0" izz="1.0"/>
    </inertial>
  </link>
  
  <link name="back_support_of_steering_wheel_frame">
    <visual>
      <geometry>
        <cylinder radius="0.0025" length="0.0025"/>
      </geometry>
      <origin rpy="0 0 0" xyz="0 0 0"/>
      <material name="white"/>
    </visual>
    <collision>
      <geometry>
        <cylinder radius="0.0025" length="0.0025"/>
      </geometry>
      <origin rpy="0 0 0" xyz="0 0 0"/>
    </collision>
    <inertial>
      <mass value="10.0"/>
      <inertia ixx="1.0" ixy="0.0" ixz="0.0" iyy="1.0" iyz="0.0" izz="1.0"/>
    </inertial>
  </link>
  
  <link name="front_steering_wheel_frame">
    <visual>
      <geometry>
        <mesh filename="package://model/meshes/dashgoD1_steering_wheel_frame.stl"/>
      </geometry>
      <origin rpy="1.57075 0 1.57075" xyz="-0.0095 -0.017 -0.0375"/>
    </visual>
    <collision>
      <geometry>
        <mesh filename="package://model/meshes/dashgoD1_steering_wheel_frame.stl"/>
      </geometry>
      <origin rpy="1.57075 0 1.57075" xyz="-0.0095 -0.017 -0.0375"/>
    </collision>
    <inertial>
      <mass value="10.0"/>
      <inertia ixx="1.0" ixy="0.0" ixz="0.0" iyy="1.0" iyz="0.0" izz="1.0"/>
    </inertial>
  </link>
  
  <link name="back_steering_wheel_frame">
    <visual>
      <geometry>
        <mesh filename="package://model/meshes/dashgoD1_steering_wheel_frame.stl"/>
      </geometry>
      <origin rpy="1.57075 0 1.57075" xyz="-0.0095 -0.017 -0.0375"/>
    </visual>
    <collision>
      <geometry>
        <mesh filename="package://model/meshes/dashgoD1_steering_wheel_frame.stl"/>
      </geometry>
      <origin rpy="1.57075 0 1.57075" xyz="-0.0095 -0.017 -0.0375"/>
    </collision>
    <inertial>
      <mass value="10.0"/>
      <inertia ixx="1.0" ixy="0.0" ixz="0.0" iyy="1.0" iyz="0.0" izz="1.0"/>
    </inertial>
  </link>
  
  <link name="front_steering_wheel">
    <visual>
      <geometry>
        <cylinder radius="0.0125" length="0.015"/>
      </geometry>
      <origin rpy="0 1.57075 0" xyz="0 0 0"/>
      <material name="white"/>
    </visual>
    <collision>
      <geometry>
        <cylinder radius="0.0125" length="0.015"/>
      </geometry>
      <origin rpy="0 1.57075 0" xyz="0 0 0"/>
    </collision>
    <inertial>
      <mass value="10.0"/>
      <inertia ixx="1.0" ixy="0.0" ixz="0.0" iyy="1.0" iyz="0.0" izz="1.0"/>
    </inertial>
  </link>
  
  <link name="back_steering_wheel">
    <visual>
      <geometry>
        <cylinder radius="0.0125" length="0.015"/>
      </geometry>
      <origin rpy="0 1.57075 0" xyz="0 0 0"/>
      <material name="white"/>
    </visual>
    <collision>
      <geometry>
        <cylinder radius="0.0125" length="0.015"/>
      </geometry>
      <origin rpy="0 1.57075 0" xyz="0 0 0"/>
    </collision>
    <inertial>
      <mass value="10.0"/>
      <inertia ixx="1.0" ixy="0.0" ixz="0.0" iyy="1.0" iyz="0.0" izz="1.0"/>
    </inertial>
  </link>
  
  <link name="laser_frame">
    <visual>
      <geometry>
        <cylinder radius="0.035" length="0.060"/>
      </geometry>
      <origin xyz="0 0 0"/>
    </visual>
    <collision>
      <geometry>
        <cylinder radius="0.035" length="0.060"/>
      </geometry>
      <origin xyz="0 0 0"/> 
    </collision>
    <inertial>
      <mass value="10.0"/>
      <inertia ixx="1.0" ixy="0.0" ixz="0.0" iyy="1.0" iyz="0.0" izz="1.0"/>
    </inertial>
  </link>
  
  <link name="laser_sensor">
    <visual>
      <geometry>
        <box size="0.01 0.01 0.01"/>
      </geometry>
      <origin xyz="0.0 0.0 0.0" rpy="0.0 0.0 0.0"/>
    </visual> 
    <collision>
      <geometry>
        <box size="0.01 0.01 0.01"/>
      </geometry>
      <origin xyz="0.0 0.0 0.0" rpy="0.0 0.0 0.0"/>
    </collision>
    <inertial>
      <mass value="1e-5" />
      <origin xyz="0 0 0" rpy="0 0 0"/>
      <inertia ixx="1e-6" ixy="0" ixz="0" iyy="1e-6" iyz="0" izz="1e-6" />>
    </inertial>
  </link>

  <!-- joints -->
  <joint name="base_to_body" type="fixed">
     <parent link="base_link"/>
     <child link="body_link"/>
     <origin xyz="0 0 0" rpy="0 0 1.57075"/>
  </joint>

  <joint name="left_motor" type="continuous">
    <parent link="body_link"/>
    <child link="left_leg"/>
    <origin xyz="0 0 0.0625" rpy="0 0 0"/>
    <axis xyz="1 0 0"/>
    <dynamics damping="0.7"/>
  </joint>
  
  <joint name="right_motor" type="continuous">
    <parent link="body_link"/>
    <child link="right_leg"/>
    <origin xyz="0 0 0.0625" rpy="0 0 0"/>
    <axis xyz="1 0 0"/>
    <dynamics damping="0.7"/>
  </joint>
  
  <joint name="body_link_to_front_support_of_steering_wheel_frame" type="fixed">
    <parent link="body_link"/>
    <child link="front_support_of_steering_wheel_frame"/>
    <origin xyz="0 -0.130 0.038"/>
  </joint>
  
  <joint name="body_link_to_back_support_of_steering_wheel_frame" type="fixed">
    <parent link="body_link"/>
    <child link="back_support_of_steering_wheel_frame"/>
    <origin xyz="0 0.130 0.038"/>
  </joint>
  
  <joint name="front_support_to_front_steering_wheel_frame" type="fixed">
    <parent link="front_support_of_steering_wheel_frame"/>
    <child link="front_steering_wheel_frame"/>
    <origin xyz="0 0 0"/>
  </joint>
  
  <joint name="back_support_to_front_steering_wheel_frame" type="fixed">
    <parent link="back_support_of_steering_wheel_frame"/>
    <child link="back_steering_wheel_frame"/>
    <origin xyz="0 0 0"/>
  </joint>
  
  <joint name="front_steering_wheel_frame_to_wheel" type="continuous">
    <parent link="front_steering_wheel_frame"/>
    <child link="front_steering_wheel"/>
    <origin xyz="0.0 -0.005 -0.0255"/>
  </joint>
  
  <joint name="back_steering_wheel_frame_to_wheel" type="continuous">
    <parent link="back_steering_wheel_frame"/>
    <child link="back_steering_wheel"/>
    <origin xyz="0.0 -0.005 -0.0255"/>
  </joint>
  
  <joint name="body_link_to_laser_frame" type="fixed">
    <parent link="body_link"/>
    <child link="laser_frame"/>
    <origin xyz="0 0 0.226"/>
  </joint>
  
  <joint name="laser_frame_to_laser_sensor" type="fixed">
    <parent link="laser_frame"/>
    <child link="laser_sensor"/>
    <origin xyz="0.0 0.0 0.010" rpy="0.0 0.0 0.0" />
  </joint>

  <!-- transmissions -->
  <transmission name="tran1">
    <type>transmission_interface/SimpleTransmission</type>
    <joint name="left_motor">
      <hardwareInterface>hardware_interface/VelocityJointInterface</hardwareInterface>
    </joint>
    <actuator name="left_leg">
      <hardwareInterface>hardware_interface/VelocityJointInterface</hardwareInterface>
      <mechanicalReduction>1</mechanicalReduction>
    </actuator>
  </transmission>

  <transmission name="tran2">
    <type>transmission_interface/SimpleTransmission</type>
    <joint name="right_motor">
      <hardwareInterface>hardware_interface/VelocityJointInterface</hardwareInterface>
    </joint>
    <actuator name="right_leg">
      <hardwareInterface>hardware_interface/VelocityJointInterface</hardwareInterface>
      <mechanicalReduction>1</mechanicalReduction>
    </actuator>
  </transmission>
</robot>